<sdf version='1.7'>
  <model name='porter_bot'>
    <link name='base_link'>
      <inertial>
        <pose>0 0 0.002171 1.5708 -0 1.5708</pose>
        <mass>15.2</mass>
        <inertia>
          <ixx>0.0523763</ixx>
          <ixy>1.36846e-48</ixy>
          <ixz>-1.54074e-33</ixz>
          <iyy>0.0401979</iyy>
          <iyz>-2.88329e-18</iyz>
          <izz>0.0274075</izz>
        </inertia>
      </inertial>
      <collision name='base_link_collision'>
        <pose>0 0 0 0 -0 0</pose>
        <geometry>
          <box>
            <size>0.16 0.075 0.085</size>
          </box>
        </geometry>
      </collision>
      <collision name='base_link_fixed_joint_lump__imu_link_collision_1'>
        <pose>0 0 0.01 0 -0 0</pose>
        <geometry>
          <box>
            <size>0.1 0.1 0.1</size>
          </box>
        </geometry>
        <surface>
          <contact>
            <ode/>
          </contact>
          <friction>
            <ode/>
          </friction>
        </surface>
      </collision>
      <collision name='base_link_fixed_joint_lump__lidar_link_collision_2'>
        <pose>0 0 0.32 0 -0 0</pose>
        <geometry>
          <cylinder>
            <length>0.035</length>
            <radius>0.0308</radius>
          </cylinder>
        </geometry>
        <surface>
          <contact>
            <ode/>
          </contact>
          <friction>
            <ode/>
          </friction>
        </surface>
      </collision>
      <visual name='base_link_visual'>
        <pose>0 0 0 0 -0 0</pose>
        <geometry>
          <box>
            <size>0.16 0.075 0.085</size>
          </box>
        </geometry>
      </visual>
      <visual name='base_link_fixed_joint_lump__imu_link_visual_1'>
        <pose>0 0 0.01 0 -0 0</pose>
        <geometry>
          <box>
            <size>0.1 0.1 0.1</size>
          </box>
        </geometry>
      </visual>
      <visual name='base_link_fixed_joint_lump__lidar_link_visual_2'>
        <pose>0 0 0.32 0 -0 0</pose>
        <geometry>
          <cylinder>
            <length>0.055</length>
            <radius>0.0508</radius>
          </cylinder>
        </geometry>
      </visual>
      <sensor name='imu_sensor' type='imu'>
        <plugin name='imu_plugin' filename='libgazebo_ros_imu_sensor.so'>
          <ros>
            <namespace>/demo</namespace>
            <remapping>~/out:=imu</remapping>
          </ros>
          <initial_orientation_as_reference>0</initial_orientation_as_reference>
        </plugin>
        <always_on>1</always_on>
        <update_rate>100</update_rate>
        <visualize>1</visualize>
        <imu>
          <angular_velocity>
            <x>
              <noise type='gaussian'>
                <mean>0</mean>
                <stddev>0.0002</stddev>
                <bias_mean>7.5e-06</bias_mean>
                <bias_stddev>8e-07</bias_stddev>
              </noise>
            </x>
            <y>
              <noise type='gaussian'>
                <mean>0</mean>
                <stddev>0.0002</stddev>
                <bias_mean>7.5e-06</bias_mean>
                <bias_stddev>8e-07</bias_stddev>
              </noise>
            </y>
            <z>
              <noise type='gaussian'>
                <mean>0</mean>
                <stddev>0.0002</stddev>
                <bias_mean>7.5e-06</bias_mean>
                <bias_stddev>8e-07</bias_stddev>
              </noise>
            </z>
          </angular_velocity>
          <linear_acceleration>
            <x>
              <noise type='gaussian'>
                <mean>0</mean>
                <stddev>0.017</stddev>
                <bias_mean>0.1</bias_mean>
                <bias_stddev>0.001</bias_stddev>
              </noise>
            </x>
            <y>
              <noise type='gaussian'>
                <mean>0</mean>
                <stddev>0.017</stddev>
                <bias_mean>0.1</bias_mean>
                <bias_stddev>0.001</bias_stddev>
              </noise>
            </y>
            <z>
              <noise type='gaussian'>
                <mean>0</mean>
                <stddev>0.017</stddev>
                <bias_mean>0.1</bias_mean>
                <bias_stddev>0.001</bias_stddev>
              </noise>
            </z>
          </linear_acceleration>
        </imu>
        <pose>0 0 0.01 0 -0 0</pose>
      </sensor>
      <sensor name='lidar' type='ray'>
        <always_on>1</always_on>
        <visualize>1</visualize>
        <update_rate>5</update_rate>
        <ray>
          <scan>
            <horizontal>
              <samples>360</samples>
              <resolution>1</resolution>
              <min_angle>0</min_angle>
              <max_angle>6.28</max_angle>
            </horizontal>
          </scan>
          <range>
            <min>0.12</min>
            <max>3.5</max>
            <resolution>0.015</resolution>
          </range>
          <noise>
            <type>gaussian</type>
            <mean>0</mean>
            <stddev>0.01</stddev>
          </noise>
        </ray>
        <plugin name='scan' filename='libgazebo_ros_ray_sensor.so'>
          <ros>
            <remapping>~/out:=scan</remapping>
          </ros>
          <output_type>sensor_msgs/LaserScan</output_type>
          <frame_name>lidar_link</frame_name>
        </plugin>
        <pose>0 0 0.32 0 -0 0</pose>
      </sensor>
    </link>
    <joint name='frontwhl_l_joint' type='revolute'>
      <pose relative_to='base_link'>0.035 0.0485 -0.0305 0 -0 0</pose>
      <parent>base_link</parent>
      <child>frontwhl_l_link</child>
      <axis>
        <xyz>0 1 0</xyz>
        <limit>
          <lower>-1e+16</lower>
          <upper>1e+16</upper>
        </limit>
        <dynamics>
          <spring_reference>0</spring_reference>
          <spring_stiffness>0</spring_stiffness>
        </dynamics>
      </axis>
    </joint>
    <link name='frontwhl_l_link'>
      <pose relative_to='frontwhl_l_joint'>0 0 0 0 -0 0</pose>
      <inertial>
        <pose>0 0 0 1.5708 -0 0</pose>
        <mass>0.5</mass>
        <inertia>
          <ixx>0.000116667</ixx>
          <ixy>0</ixy>
          <ixz>0</ixz>
          <iyy>0.000116667</iyy>
          <iyz>0</iyz>
          <izz>0.000225</izz>
        </inertia>
      </inertial>
      <collision name='frontwhl_l_link_collision'>
        <pose>0 0 0 1.5708 -0 0</pose>
        <geometry>
          <cylinder>
            <length>0.01</length>
            <radius>0.03</radius>
          </cylinder>
        </geometry>
      </collision>
      <visual name='frontwhl_l_link_visual'>
        <pose>0 0 0 1.5708 -0 0</pose>
        <geometry>
          <cylinder>
            <length>0.01</length>
            <radius>0.03</radius>
          </cylinder>
        </geometry>
      </visual>
    </link>
    <joint name='frontwhl_r_joint' type='revolute'>
      <pose relative_to='base_link'>0.035 -0.0485 -0.0305 0 -0 0</pose>
      <parent>base_link</parent>
      <child>frontwhl_r_link</child>
      <axis>
        <xyz>0 1 0</xyz>
        <limit>
          <lower>-1e+16</lower>
          <upper>1e+16</upper>
        </limit>
        <dynamics>
          <spring_reference>0</spring_reference>
          <spring_stiffness>0</spring_stiffness>
        </dynamics>
      </axis>
    </joint>
    <link name='frontwhl_r_link'>
      <pose relative_to='frontwhl_r_joint'>0 0 0 0 -0 0</pose>
      <inertial>
        <pose>0 0 0 1.5708 -0 0</pose>
        <mass>0.5</mass>
        <inertia>
          <ixx>0.000116667</ixx>
          <ixy>0</ixy>
          <ixz>0</ixz>
          <iyy>0.000116667</iyy>
          <iyz>0</iyz>
          <izz>0.000225</izz>
        </inertia>
      </inertial>
      <collision name='frontwhl_r_link_collision'>
        <pose>0 0 0 1.5708 -0 0</pose>
        <geometry>
          <cylinder>
            <length>0.01</length>
            <radius>0.03</radius>
          </cylinder>
        </geometry>
      </collision>
      <visual name='frontwhl_r_link_visual'>
        <pose>0 0 0 1.5708 -0 0</pose>
        <geometry>
          <cylinder>
            <length>0.01</length>
            <radius>0.03</radius>
          </cylinder>
        </geometry>
      </visual>
    </link>
    <joint name='rearwhl_l_joint' type='revolute'>
      <pose relative_to='base_link'>-0.062 0.0485 -0.0305 0 -0 0</pose>
      <parent>base_link</parent>
      <child>rearwhl_l_link</child>
      <axis>
        <xyz>0 1 0</xyz>
        <limit>
          <lower>-1e+16</lower>
          <upper>1e+16</upper>
        </limit>
        <dynamics>
          <spring_reference>0</spring_reference>
          <spring_stiffness>0</spring_stiffness>
        </dynamics>
      </axis>
    </joint>
    <link name='rearwhl_l_link'>
      <pose relative_to='rearwhl_l_joint'>0 0 0 0 -0 0</pose>
      <inertial>
        <pose>0 0 0 1.5708 -0 0</pose>
        <mass>0.5</mass>
        <inertia>
          <ixx>0.000116667</ixx>
          <ixy>0</ixy>
          <ixz>0</ixz>
          <iyy>0.000116667</iyy>
          <iyz>0</iyz>
          <izz>0.000225</izz>
        </inertia>
      </inertial>
      <collision name='rearwhl_l_link_collision'>
        <pose>0 0 0 1.5708 -0 0</pose>
        <geometry>
          <cylinder>
            <length>0.01</length>
            <radius>0.03</radius>
          </cylinder>
        </geometry>
      </collision>
      <visual name='rearwhl_l_link_visual'>
        <pose>0 0 0 1.5708 -0 0</pose>
        <geometry>
          <cylinder>
            <length>0.01</length>
            <radius>0.03</radius>
          </cylinder>
        </geometry>
      </visual>
    </link>
    <joint name='rearwhl_r_joint' type='revolute'>
      <pose relative_to='base_link'>-0.062 -0.0485 -0.0305 0 -0 0</pose>
      <parent>base_link</parent>
      <child>rearwhl_r_link</child>
      <axis>
        <xyz>0 1 0</xyz>
        <limit>
          <lower>-1e+16</lower>
          <upper>1e+16</upper>
        </limit>
        <dynamics>
          <spring_reference>0</spring_reference>
          <spring_stiffness>0</spring_stiffness>
        </dynamics>
      </axis>
    </joint>
    <link name='rearwhl_r_link'>
      <pose relative_to='rearwhl_r_joint'>0 0 0 0 -0 0</pose>
      <inertial>
        <pose>0 0 0 1.5708 -0 0</pose>
        <mass>0.5</mass>
        <inertia>
          <ixx>0.000116667</ixx>
          <ixy>0</ixy>
          <ixz>0</ixz>
          <iyy>0.000116667</iyy>
          <iyz>0</iyz>
          <izz>0.000225</izz>
        </inertia>
      </inertial>
      <collision name='rearwhl_r_link_collision'>
        <pose>0 0 0 1.5708 -0 0</pose>
        <geometry>
          <cylinder>
            <length>0.01</length>
            <radius>0.03</radius>
          </cylinder>
        </geometry>
      </collision>
      <visual name='rearwhl_r_link_visual'>
        <pose>0 0 0 1.5708 -0 0</pose>
        <geometry>
          <cylinder>
            <length>0.01</length>
            <radius>0.03</radius>
          </cylinder>
        </geometry>
      </visual>
    </link>
    <plugin name='porter_diff_drive' filename='libgazebo_ros_diff_drive.so'>
      <ros>
        <namespace>/demo</namespace>
      </ros>
      <left_joint>rearwhl_l_joint</left_joint>
      <right_joint>rearwhl_r_joint</right_joint>
      <wheel_separation>0.011</wheel_separation>
      <wheel_diameter>0.06</wheel_diameter>
      <max_wheel_torque>20</max_wheel_torque>
      <max_wheel_acceleration>1.0</max_wheel_acceleration>
      <publish_odom>1</publish_odom>
      <publish_odom_tf>1</publish_odom_tf>
      <publish_wheel_tf>1</publish_wheel_tf>
      <odometry_frame>odom</odometry_frame>
      <robot_base_frame>base_link</robot_base_frame>
    </plugin>
    <static>0</static>
    <plugin name='porter_diff_drive' filename='libgazebo_ros_diff_drive.so'>
      <ros>
        <namespace>/demo</namespace>
      </ros>
      <left_joint>frontwhl_l_joint</left_joint>
      <right_joint>frontwhl_r_joint</right_joint>
      <wheel_separation>0.011</wheel_separation>
      <wheel_diameter>0.06</wheel_diameter>
      <max_wheel_torque>20</max_wheel_torque>
      <max_wheel_acceleration>1.0</max_wheel_acceleration>
      <publish_odom>1</publish_odom>
      <publish_odom_tf>1</publish_odom_tf>
      <publish_wheel_tf>1</publish_wheel_tf>
      <odometry_frame>odom</odometry_frame>
      <robot_base_frame>base_link</robot_base_frame>
    </plugin>
  </model>
</sdf>
